Workbook

Sheet Dashboard
B5: Latest Month | E5: Top Broad Category | H5: Peak YoY Inflation Year
B6: 45047 | E6: Pan/Tobacco | H6: 2022
B7: Final month used for analysis | E7: Highest Contribution In latest month | H7: Highest average inflation in the series
B9: Highest Food Inflation Month | E9: Strongest Oil Linkage Category | H9: COVID Benchmark
B10: 44986 | E10: Transport | H10: 43891
B11: Within 12 months ending May 2023 | E11: Highest correlation with Fuel proxy | H11: First Lockdown onset month
A104: Source: Government of India CPI dataset. Dashboard prepared from workbook analysis.

Sheet Raw Data
A1: Sector | B1: Year | C1: Month | D1: Cereals and products | E1: Meat and fish | F1: Egg | G1: Milk and products | H1: Oils and fats | I1: Fruits | J1: Vegetables | K1: Pulses and products | L1: Sugar and Confectionery | M1: Spices | N1: Non-alcoholic beverages | O1: Prepared meals, snacks, sweets etc. | P1: Food and beverages | Q1: Pan, tobacco and intoxicants | R1: Clothing | S1: Footwear | T1: Clothing and footwear | U1: Housing | V1: Fuel and light | W1: Household goods and services | X1: Health | Y1: Transport and communication | Z1: Recreation and amusement | AA1: Education | AB1: Personal care and effects | AC1: Miscellaneous | AD1: General index
A2: Rural | B2: 2013 | C2: January | D2: 107.5 | E2: 106.3 | F2: 108.1 | G2: 104.9 | H2: 106.1 | I2: 103.9 | J2: 101.9 | K2: 106.1 | L2: 106.8 | M2: 103.1 | N2: 104.8 | O2: 106.7 | P2: 105.5 | Q2: 105.1 | R2: 106.5 | S2: 105.8 | T2: 106.4 | U2: NA | V2: 105.5 | W2: 104.8 | X2: 104 | Y2: 103.3 | Z2: 103.4 | AA2: 103.8 | AB2: 104.7 | AC2: 104 | AD2: 105.1
A3: Urban | B3: 2013 | C3: January | D3: 110.5 | E3: 109.1 | F3: 113 | G3: 103.6 | H3: 103.4 | I3: 102.3 | J3: 102.9 | K3: 105.8 | L3: 105.1 | M3: 101.8 | N3: 105.1 | O3: 107.9 | P3: 105.9 | Q3: 105.2 | R3: 105.9 | S3: 105 | T3: 105.8 | U3: 100.3 | V3: 105.4 | W3: 104.8 | X3: 104.1 | Y3: 103.2 | Z3: 102.9 | AA3: 103.5 | AB3: 104.3 | AC3: 103.7 | AD3: 104
A4: Rural+Urban | B4: 2013 | C4: January | D4: 108.4 | E4: 107.3 | F4: 110 | G4: 104.4 | H4: 105.1 | I4: 103.2 | J4: 102.2 | K4: 106 | L4: 106.2 | M4: 102.7 | N4: 104.9 | O4: 107.3 | P4: 105.6 | Q4: 105.1 | R4: 106.3 | S4: 105.5 | T4: 106.2 | U4: 100.3 | V4: 105.5 | W4: 104.8 | X4: 104 | Y4: 103.2 | Z4: 103.1 | AA4: 103.6 | AB4: 104.5 | AC4: 103.9 | AD4: 104.6
A5: Rural | B5: 2013 | C5: February | D5: 109.2 | E5: 108.7 | F5: 110.2 | G5: 105.4 | H5: 106.7 | I5: 104 | J5: 102.4 | K5: 105.9 | L5: 105.7 | M5: 103.1 | N5: 105.1 | O5: 107.7 | P5: 106.3 | Q5: 105.6 | R5: 107.1 | S5: 106.3 | T5: 107 | U5: NA | V5: 106.2 | W5: 105.2 | X5: 104.4 | Y5: 103.9 | Z5: 104 | AA5: 104.1 | AB5: 104.6 | AC5: 104.4 | AD5: 105.8
A6: Urban | B6: 2013 | C6: February | D6: 112.9 | E6: 112.9 | F6: 116.9 | G6: 104 | H6: 103.5 | I6: 103.1 | J6: 104.9 | K6: 104.1 | L6: 103.8 | M6: 102.3 | N6: 106 | O6: 109 | P6: 107.2 | Q6: 106 | R6: 106.6 | S6: 105.5 | T6: 106.4 | U6: 100.4 | V6: 105.7 | W6: 105.2 | X6: 104.7 | Y6: 104.4 | Z6: 103.3 | AA6: 103.7 | AB6: 104.3 | AC6: 104.3 | AD6: 104.7
A7: Rural+Urban | B7: 2013 | C7: February | D7: 110.4 | E7: 110.2 | F7: 112.8 | G7: 104.9 | H7: 105.5 | I7: 103.6 | J7: 103.2 | K7: 105.3 | L7: 105.1 | M7: 102.8 | N7: 105.5 | O7: 108.3 | P7: 106.6 | Q7: 105.7 | R7: 106.9 | S7: 106 | T7: 106.8 | U7: 100.4 | V7: 106 | W7: 105.2 | X7: 104.5 | Y7: 104.2 | Z7: 103.6 | AA7: 103.9 | AB7: 104.5 | AC7: 104.4 | AD7: 105.3
A8: Rural | B8: 2013 | C8: March | D8: 110.2 | E8: 108.8 | F8: 109.9 | G8: 105.6 | H8: 106.2 | I8: 105.7 | J8: 101.4 | K8: 105.7 | L8: 105 | M8: 103.3 | N8: 105.6 | O8: 108.2 | P8: 106.6 | Q8: 106.5 | R8: 107.6 | S8: 106.8 | T8: 107.5 | U8: NA | V8: 106.1 | W8: 105.6 | X8: 104.7 | Y8: 104.6 | Z8: 104 | AA8: 104.3 | AB8: 104.3 | AC8: 104.6 | AD8: 106
A9: Urban | B9: 2013 | C9: March | D9: 113.9 | E9: 111.4 | F9: 113.2 | G9: 104.3 | H9: 102.7 | I9: 104.9 | J9: 103.8 | K9: 103.5 | L9: 102.6 | M9: 102.4 | N9: 107 | O9: 109.8 | P9: 107.3 | Q9: 106.8 | R9: 107.2 | S9: 106 | T9: 107 | U9: 100.4 | V9: 106 | W9: 105.7 | X9: 105.2 | Y9: 105.5 | Z9: 103.5 | AA9: 103.8 | AB9: 104.2 | AC9: 104.9 | AD9: 105
A10: Rural+Urban | B10: 2013 | C10: March | D10: 111.4 | E10: 109.7 | F10: 111.2 | G10: 105.1 | H10: 104.9 | I10: 105.3 | J10: 102.2 | K10: 105 | L10: 104.2 | M10: 103 | N10: 106.2 | O10: 108.9 | P10: 106.9 | Q10: 106.6 | R10: 107.4 | S10: 106.5 | T10: 107.3 | U10: 100.4 | V10: 106.1 | W10: 105.6 | X10: 104.9 | Y10: 105.1 | Z10: 103.7 | AA10: 104 | AB10: 104.3 | AC10: 104.7 | AD10: 105.5
A11: Rural | B11: 2013 | C11: April | D11: 110.2 | E11: 109.5 | F11: 106.9 | G11: 106.3 | H11: 105.7 | I11: 108.3 | J11: 103.4 | K11: 105.7 | L11: 104.2 | M11: 103.2 | N11: 106.5 | O11: 108.8 | P11: 107.1 | Q11: 107.1 | R11: 108.1 | S11: 107.4 | T11: 108 | U11: NA | V11: 106.5 | W11: 106.1 | X11: 105.1 | Y11: 104.4 | Z11: 104.5 | AA11: 104.8 | AB11: 102.7 | AC11: 104.6 | AD11: 106.4
A12: Urban | B12: 2013 | C12: April | D12: 114.6 | E12: 113.4 | F12: 106 | G12: 104.7 | H12: 102.1 | I12: 109.5 | J12: 109.7 | K12: 104.6 | L12: 102 | M12: 103.5 | N12: 108.2 | O12: 110.6 | P12: 108.8 | Q12: 108.5 | R12: 107.9 | S12: 106.4 | T12: 107.7 | U12: 100.5 | V12: 106.4 | W12: 106.5 | X12: 105.7 | Y12: 105 | Z12: 104 | AA12: 105.2 | AB12: 103.2 | AC12: 105.1 | AD12: 105.7
A13: Rural+Urban | B13: 2013 | C13: April | D13: 111.6 | E13: 110.9 | F13: 106.6 | G13: 105.7 | H13: 104.4 | I13: 108.9 | J13: 105.5 | K13: 105.3 | L13: 103.5 | M13: 103.3 | N13: 107.2 | O13: 109.6 | P13: 107.7 | Q13: 107.5 | R13: 108 | S13: 107 | T13: 107.9 | U13: 100.5 | V13: 106.5 | W13: 106.3 | X13: 105.3 | Y13: 104.7 | Z13: 104.2 | AA13: 105 | AB13: 102.9 | AC13: 104.8 | AD13: 106.1
A14: Rural | B14: 2013 | C14: May | D14: 110.9 | E14: 109.8 | F14: 105.9 | G14: 107.5 | H14: 105.3 | I14: 108.1 | J14: 107.3 | K14: 106.1 | L14: 103.7 | M14: 104 | N14: 107.4 | O14: 109.9 | P14: 108.1 | Q14: 108.1 | R14: 108.8 | S14: 107.9 | T14: 108.6 | U14: NA | V14: 107.5 | W14: 106.8 | X14: 105.7 | Y14: 104.1 | Z14: 105 | AA14: 105.5 | AB14: 102.1 | AC14: 104.8 | AD14: 107.2
A15: Urban | B15: 2013 | C15: May | D15: 115.4 | E15: 114.2 | F15: 102.7 | G15: 105.5 | H15: 101.5 | I15: 110.6 | J15: 123.7 | K15: 105.2 | L15: 101.9 | M15: 105 | N15: 109.1 | O15: 111.3 | P15: 111.1 | Q15: 109.8 | R15: 108.5 | S15: 106.7 | T15: 108.3 | U15: 100.5 | V15: 107.2 | W15: 107.1 | X15: 106.2 | Y15: 103.9 | Z15: 104.6 | AA15: 105.7 | AB15: 102.6 | AC15: 104.9 | AD15: 106.6
A16: Rural+Urban | B16: 2013 | C16: May | D16: 112.3 | E16: 111.3 | F16: 104.7 | G16: 106.8 | H16: 103.9 | I16: 109.3 | J16: 112.9 | K16: 105.8 | L16: 103.1 | M16: 104.3 | N16: 108.1 | O16: 110.5 | P16: 109.2 | Q16: 108.6 | R16: 108.7 | S16: 107.4 | T16: 108.5 | U16: 100.5 | V16: 107.4 | W16: 106.9 | X16: 105.9 | Y16: 104 | Z16: 104.8 | AA16: 105.6 | AB16: 102.3 | AC16: 104.8 | AD16: 106.9
A17: Rural | B17: 2013 | C17: June | D17: 112.3 | E17: 112.1 | F17: 108.1 | G17: 108.3 | H17: 105.9 | I17: 109.2 | J17: 118 | K17: 106.8 | L17: 104.1 | M17: 105.4 | N17: 108.2 | O17: 111 | P17: 110.6 | Q17: 109 | R17: 109.7 | S17: 108.8 | T17: 109.5 | U17: NA | V17: 108.5 | W17: 107.5 | X17: 106.3 | Y17: 105 | Z17: 105.6 | AA17: 106.5 | AB17: 102.5 | AC17: 105.5 | AD17: 108.9
A18: Urban | B18: 2013 | C18: June | D18: 117 | E18: 120.1 | F18: 112.5 | G18: 107.3 | H18: 101.3 | I18: 112.4 | J18: 143.6 | K18: 105.4 | L18: 101.4 | M18: 106.4 | N18: 110 | O18: 112.2 | P18: 115 | Q18: 110.9 | R18: 109.2 | S18: 107.2 | T18: 108.9 | U18: 106.6 | V18: 108 | W18: 107.7 | X18: 106.5 | Y18: 105.2 | Z18: 105.2 | AA18: 108.1 | AB18: 103.3 | AC18: 106.1 | AD18: 109.7
A19: Rural+Urban | B19: 2013 | C19: June | D19: 113.8 | E19: 114.9 | F19: 109.8 | G19: 107.9 | H19: 104.2 | I19: 110.7 | J19: 126.7 | K19: 106.3 | L19: 103.2 | M19: 105.7 | N19: 109 | O19: 111.6 | P19: 112.2 | Q19: 109.5 | R19: 109.5 | S19: 108.1 | T19: 109.3 | U19: 106.6 | V19: 108.3 | W19: 107.6 | X19: 106.4 | Y19: 105.1 | Z19: 105.4 | AA19: 107.4 | AB19: 102.8 | AC19: 105.8 | AD19: 109.3
A20: Rural | B20: 2013 | C20: July | D20: 113.4 | E20: 114.9 | F20: 110.5 | G20: 109.3 | H20: 106.2 | I20: 110.3 | J20: 129.2 | K20: 107.1 | L20: 104.3 | M20: 106.4 | N20: 109.1 | O20: 112.1 | P20: 113.1 | Q20: 109.8 | R20: 110.5 | S20: 109.5 | T20: 110.3 | U20: NA | V20: 109.5 | W20: 108.3 | X20: 106.9 | Y20: 106.8 | Z20: 106.4 | AA20: 107.8 | AB20: 102.5 | AC20: 106.5 | AD20: 110.7
A21: Urban | B21: 2013 | C21: July | D21: 117.8 | E21: 119.2 | F21: 114 | G21: 108.3 | H21: 101.1 | I21: 113.2 | J21: 160.9 | K21: 105.1 | L21: 101.3 | M21: 107.5 | N21: 110.4 | O21: 113.1 | P21: 117.5 | Q21: 111.7 | R21: 109.8 | S21: 107.8 | T21: 109.5 | U21: 107.7 | V21: 108.6 | W21: 108.1 | X21: 107.1 | Y21: 107.3 | Z21: 105.9 | AA21: 110.1 | AB21: 103.2 | AC21: 107.3 | AD21: 111.4
A22: Rural+Urban | B22: 2013 | C22: July | D22: 114.8 | E22: 116.4 | F22: 111.9 | G22: 108.9 | H22: 104.3 | I22: 111.7 | J22: 140 | K22: 106.4 | L22: 103.3 | M22: 106.8 | N22: 109.6 | O22: 112.6 | P22: 114.7 | Q22: 110.3 | R22: 110.2 | S22: 108.8 | T22: 110 | U22: 107.7 | V22: 109.2 | W22: 108.2 | X22: 107 | Y22: 107.1 | Z22: 106.1 | AA22: 109.1 | AB22: 102.8 | AC22: 106.9 | AD22: 111
A23: Rural | B23: 2013 | C23: August | D23: 114.3 | E23: 115.4 | F23: 111.1 | G23: 110 | H23: 106.4 | I23: 110.8 | J23: 138.9 | K23: 107.4 | L23: 104.1 | M23: 106.9 | N23: 109.7 | O23: 112.6 | P23: 114.9 | Q23: 110.7 | R23: 111.3 | S23: 110.2 | T23: 111.1 | U23: NA | V23: 109.9 | W23: 108.7 | X23: 107.5 | Y23: 107.8 | Z23: 106.8 | AA23: 108.7 | AB23: 105 | AC23: 107.5 | AD23: 112.1
A24: Urban | B24: 2013 | C24: August | D24: 118.3 | E24: 120.4 | F24: 112.7 | G24: 108.9 | H24: 101.1 | I24: 108.7 | J24: 177 | K24: 104.7 | L24: 101 | M24: 108.5 | N24: 110.9 | O24: 114.3 | P24: 119.6 | Q24: 112.4 | R24: 110.6 | S24: 108.3 | T24: 110.2 | U24: 108.9 | V24: 109.3 | W24: 108.7 | X24: 107.6 | Y24: 108.1 | Z24: 106.5 | AA24: 110.8 | AB24: 106 | AC24: 108.3 | AD24: 112.7
A25: Rural+Urban | B25: 2013 | C25: August | D25: 115.6 | E25: 117.2 | F25: 111.7 | G25: 109.6 | H25: 104.5 | I25: 109.8 | J25: 151.8 | K25: 106.5 | L25: 103.1 | M25: 107.4 | N25: 110.2 | O25: 113.4 | P25: 116.6 | Q25: 111.2 | R25: 111 | S25: 109.4 | T25: 110.7 | U25: 108.9 | V25: 109.7 | W25: 108.7 | X25: 107.5 | Y25: 108 | Z25: 106.6 | AA25: 109.9 | AB25: 105.4 | AC25: 107.9 | AD25: 112.4
A26: Rural | B26: 2013 | C26: September | D26: 115.4 | E26: 115.7 | F26: 111.7 | G26: 111 | H26: 107.4 | I26: 110.9 | J26: 154 | K26: 108.1 | L26: 104.2 | M26: 107.9 | N26: 110.4 | O26: 114 | P26: 117.8 | Q26: 111.7 | R26: 112.7 | S26: 111.4 | T26: 112.5 | U26: NA | V26: 111.1 | W26: 109.6 | X26: 108.3 | Y26: 109.3 | Z26: 107.7 | AA26: 109.8 | AB26: 106.7 | AC26: 108.7 | AD26: 114.2
A27: Urban | B27: 2013 | C27: September | D27: 118.6 | E27: 119.1 | F27: 113.2 | G27: 109.6 | H27: 101.7 | I27: 103.2 | J27: 174.3 | K27: 105.1 | L27: 100.8 | M27: 109.1 | N27: 111.1 | O27: 115.4 | P27: 119.2 | Q27: 112.9 | R27: 111.4 | S27: 109 | T27: 111.1 | U27: 109.7 | V27: 109.5 | W27: 109.6 | X27: 107.9 | Y27: 110.4 | Z27: 107.4 | AA27: 111.2 | AB27: 106.9 | AC27: 109.4 | AD27: 113.2
A28: Rural+Urban | B28: 2013 | C28: September | D28: 116.4 | E28: 116.9 | F28: 112.3 | G28: 110.5 | H28: 105.3 | I28: 107.3 | J28: 160.9 | K28: 107.1 | L28: 103.1 | M28: 108.3 | N28: 110.7 | O28: 114.6 | P28: 118.3 | Q28: 112 | R28: 112.2 | S28: 110.4 | T28: 111.9 | U28: 109.7 | V28: 110.5 | W28: 109.6 | X28: 108.1 | Y28: 109.9 | Z28: 107.5 | AA28: 110.6 | AB28: 106.8 | AC28: 109 | AD28: 113.7
A29: Rural | B29: 2013 | C29: October | D29: 116.3 | E29: 115.4 | F29: 112.6 | G29: 111.7 | H29: 107.7 | I29: 113.2 | J29: 164.9 | K29: 108.3 | L29: 103.9 | M29: 108.2 | N29: 111.1 | O29: 114.9 | P29: 119.8 | Q29: 112.2 | R29: 113.6 | S29: 112.3 | T29: 113.4 | U29: NA | V29: 111.6 | W29: 110.4 | X29: 108.9 | Y29: 109.3 | Z29: 108.3 | AA29: 110.2 | AB29: 107.5 | AC29: 109.1 | AD29: 115.5
A30: Urban | B30: 2013 | C30: October | D30: 118.9 | E30: 118.1 | F30: 114.5 | G30: 110.4 | H30: 102.3 | I30: 106.2 | J30: 183.5 | K30: 105.3 | L30: 100.2 | M30: 109.6 | N30: 111.4 | O30: 116 | P30: 120.8 | Q30: 113.5 | R30: 112.5 | S30: 109.7 | T30: 112 | U30: 110.5 | V30: 109.7 | W30: 110.2 | X30: 108.2 | Y30: 109.7 | Z30: 108 | AA30: 111.3 | AB30: 107.3 | AC30: 109.4 | AD30: 114
A31: Rural+Urban | B31: 2013 | C31: October | D31: 117.1 | E31: 116.3 | F31: 113.3 | G31: 111.2 | H31: 105.7 | I31: 109.9 | J31: 171.2 | K31: 107.3 | L31: 102.7 | M31: 108.7 | N31: 111.2 | O31: 115.4 | P31: 120.2 | Q31: 112.5 | R31: 113.2 | S31: 111.2 | T31: 112.8 | U31: 110.5 | V31: 110.9 | W31: 110.3 | X31: 108.6 | Y31: 109.5 | Z31: 108.1 | AA31: 110.8 | AB31: 107.4 | AC31: 109.2 | AD31: 114.8
A32: Rural | B32: 2013 | C32: November | D32: 117.3 | E32: 114.9 | F32: 116.2 | G32: 112.8 | H32: 108.9 | I32: 116.6 | J32: 178.1 | K32: 109.1 | L32: 103.6 | M32: 109 | N32: 111.8 | O32: 116 | P32: 122.5 | Q32: 112.8 | R32: 114.6 | S32: 113.1 | T32: 114.4 | U32: NA | V32: 112.6 | W32: 111.3 | X32: 109.7 | Y32: 109.6 | Z32: 108.7 | AA32: 111 | AB32: 108.2 | AC32: 109.8 | AD32: 117.4
A33: Urban | B33: 2013 | C33: November | D33: 119.8 | E33: 116.3 | F33: 122.6 | G33: 112 | H33: 103.2 | I33: 110 | J33: 192.8 | K33: 106.3 | L33: 99.5 | M33: 110.3 | N33: 111.8 | O33: 117.1 | P33: 122.9 | Q33: 114.1 | R33: 113.5 | S33: 110.3 | T33: 113 | U33: 111.1 | V33: 110 | W33: 110.9 | X33: 108.6 | Y33: 109.5 | Z33: 108.5 | AA33: 111.3 | AB33: 107.9 | AC33: 109.6 | AD33: 115
A34: Rural+Urban | B34: 2013 | C34: November | D34: 118.1 | E34: 115.4 | F34: 118.7 | G34: 112.5 | H34: 106.8 | I34: 113.5 | J34: 183.1 | K34: 108.2 | L34: 102.2 | M34: 109.4 | N34: 111.8 | O34: 116.5 | P34: 122.6 | Q34: 113.1 | R34: 114.2 | S34: 111.9 | T34: 113.8 | U34: 111.1 | V34: 111.6 | W34: 111.1 | X34: 109.3 | Y34: 109.5 | Z34: 108.6 | AA34: 111.2 | AB34: 108.1 | AC34: 109.7 | AD34: 116.3
A35: Rural | B35: 2013 | C35: December | D35: 118.4 | E35: 115.9 | F35: 120.4 | G35: 113.8 | H35: 109.5 | I35: 115.5 | J35: 145.7 | K35: 109.5 | L35: 102.9 | M35: 109.8 | N35: 112.1 | O35: 116.8 | P35: 118.7 | Q35: 113.6 | R35: 115.8 | S35: 114 | T35: 115.5 | U35: NA | V35: 112.8 | W35: 112.1 | X35: 110.1 | Y35: 109.9 | Z35: 109.2 | AA35: 111.6 | AB35: 108.1 | AC35: 110.1 | AD35: 115.5
A36: Urban | B36: 2013 | C36: December | D36: 120.5 | E36: 118.1 | F36: 128.5 | G36: 112.8 | H36: 103.4 | I36: 110.7 | J36: 144.8 | K36: 107.1 | L36: 98.6 | M36: 111.9 | N36: 112.1 | O36: 118.1 | P36: 117.8 | Q36: 115 | R36: 114.2 | S36: 110.9 | T36: 113.7 | U36: 110.7 | V36: 110.4 | W36: 111.3 | X36: 109 | Y36: 109.7 | Z36: 108.9 | AA36: 111.4 | AB36: 107.7 | AC36: 109.8 | AD36: 113.3
A37: Rural+Urban | B37: 2013 | C37: December | D37: 119.1 | E37: 116.7 | F37: 123.5 | G37: 113.4 | H37: 107.3 | I37: 113.3 | J37: 145.4 | K37: 108.7 | L37: 101.5 | M37: 110.5 | N37: 112.1 | O37: 117.4 | P37: 118.4 | Q37: 114 | R37: 115.2 | S37: 112.7 | T37: 114.8 | U37: 110.7 | V37: 111.9 | W37: 111.7 | X37: 109.7 | Y37: 109.8 | Z37: 109 | AA37: 111.5 | AB37: 107.9 | AC37: 110 | AD37: 114.5
A38: Rural | B38: 2014 | C38: January | D38: 118.9 | E38: 117.1 | F38: 120.5 | G38: 114.4 | H38: 109 | I38: 115.5 | J38: 123.9 | K38: 109.6 | L38: 101.8 | M38: 110.2 | N38: 112.4 | O38: 117.3 | P38: 116 | Q38: 114 | R38: 116.5 | S38: 114.5 | T38: 116.2 | U38: NA | V38: 113 | W38: 112.6 | X38: 110.6 | Y38: 110.5 | Z38: 109.6 | AA38: 111.8 | AB38: 108.3 | AC38: 110.6 | AD38: 114.2
A39: Urban | B39: 2014 | C39: January | D39: 121.2 | E39: 122 | F39: 129.9 | G39: 113.6 | H39: 102.9 | I39: 112.1 | J39: 118.9 | K39: 107.5 | L39: 96.9 | M39: 112.7 | N39: 112.1 | O39: 119 | P39: 115.5 | Q39: 115.7 | R39: 114.8 | S39: 111.3 | T39: 114.3 | U39: 111.6 | V39: 111 | W39: 111.9 | X39: 109.7 | Y39: 110.8 | Z39: 109.8 | AA39: 111.5 | AB39: 108 | AC39: 110.5 | AD39: 112.9
A40: Rural+Urban | B40: 2014 | C40: January | D40: 119.6 | E40: 118.8 | F40: 124.1 | G40: 114.1 | H40: 106.8 | I40: 113.9 | J40: 122.2 | K40: 108.9 | L40: 100.2 | M40: 111 | N40: 112.3 | O40: 118.1 | P40: 115.8 | Q40: 114.5 | R40: 115.8 | S40: 113.2 | T40: 115.4 | U40: 111.6 | V40: 112.2 | W40: 112.3 | X40: 110.3 | Y40: 110.7 | Z40: 109.7 | AA40: 111.6 | AB40: 108.2 | AC40: 110.6 | AD40: 113.6
...

Sheet  YoY_Data
A1: Sector | B1: Year | C1: Month | D1: Cereals and products | E1: Meat and fish | F1: Egg | G1: Milk and products | H1: Oils and fats | I1: Fruits | J1: Vegetables | K1: Pulses and products | L1: Sugar and Confectionery | M1: Spices | N1: Non-alcoholic beverages | O1: Prepared meals, snacks, sweets etc. | P1: Pan, tobacco and intoxicants | Q1: Clothing | R1: Footwear | S1: Housing | T1: Fuel and light | U1: Household goods and services | V1: Health | W1: Transport and communication | X1: Recreation and amusement | Y1: Education | Z1: Personal care and effects | AA1: Miscellaneous | AB1: General index | AC1: Date | AD1: Genearl YoY%
A2: Rural+Urban | B2: 2013 | C2: January | D2: 108.4 | E2: 107.3 | F2: 110 | G2: 104.4 | H2: 105.1 | I2: 103.2 | J2: 102.2 | K2: 106 | L2: 106.2 | M2: 102.7 | N2: 104.9 | O2: 107.3 | P2: 105.1 | Q2: 106.3 | R2: 105.5 | S2: 100.3 | T2: 105.5 | U2: 104.8 | V2: 104 | W2: 103.2 | X2: 103.1 | Y2: 103.6 | Z2: 104.5 | AA2: 103.9 | AB2: 104.6 | AC2: 41275
A3: Rural+Urban | B3: 2013 | C3: February | D3: 110.4 | E3: 110.2 | F3: 112.8 | G3: 104.9 | H3: 105.5 | I3: 103.6 | J3: 103.2 | K3: 105.3 | L3: 105.1 | M3: 102.8 | N3: 105.5 | O3: 108.3 | P3: 105.7 | Q3: 106.9 | R3: 106 | S3: 100.4 | T3: 106 | U3: 105.2 | V3: 104.5 | W3: 104.2 | X3: 103.6 | Y3: 103.9 | Z3: 104.5 | AA3: 104.4 | AB3: 105.3 | AC3: 41306
A4: Rural+Urban | B4: 2013 | C4: March | D4: 111.4 | E4: 109.7 | F4: 111.2 | G4: 105.1 | H4: 104.9 | I4: 105.3 | J4: 102.2 | K4: 105 | L4: 104.2 | M4: 103 | N4: 106.2 | O4: 108.9 | P4: 106.6 | Q4: 107.4 | R4: 106.5 | S4: 100.4 | T4: 106.1 | U4: 105.6 | V4: 104.9 | W4: 105.1 | X4: 103.7 | Y4: 104 | Z4: 104.3 | AA4: 104.7 | AB4: 105.5 | AC4: 41334
A5: Rural+Urban | B5: 2013 | C5: April | D5: 111.6 | E5: 110.9 | F5: 106.6 | G5: 105.7 | H5: 104.4 | I5: 108.9 | J5: 105.5 | K5: 105.3 | L5: 103.5 | M5: 103.3 | N5: 107.2 | O5: 109.6 | P5: 107.5 | Q5: 108 | R5: 107 | S5: 100.5 | T5: 106.5 | U5: 106.3 | V5: 105.3 | W5: 104.7 | X5: 104.2 | Y5: 105 | Z5: 102.9 | AA5: 104.8 | AB5: 106.1 | AC5: 41365
A6: Rural+Urban | B6: 2013 | C6: May | D6: 112.3 | E6: 111.3 | F6: 104.7 | G6: 106.8 | H6: 103.9 | I6: 109.3 | J6: 112.9 | K6: 105.8 | L6: 103.1 | M6: 104.3 | N6: 108.1 | O6: 110.5 | P6: 108.6 | Q6: 108.7 | R6: 107.4 | S6: 100.5 | T6: 107.4 | U6: 106.9 | V6: 105.9 | W6: 104 | X6: 104.8 | Y6: 105.6 | Z6: 102.3 | AA6: 104.8 | AB6: 106.9 | AC6: 41395
A7: Rural+Urban | B7: 2013 | C7: June | D7: 113.8 | E7: 114.9 | F7: 109.8 | G7: 107.9 | H7: 104.2 | I7: 110.7 | J7: 126.7 | K7: 106.3 | L7: 103.2 | M7: 105.7 | N7: 109 | O7: 111.6 | P7: 109.5 | Q7: 109.5 | R7: 108.1 | S7: 106.6 | T7: 108.3 | U7: 107.6 | V7: 106.4 | W7: 105.1 | X7: 105.4 | Y7: 107.4 | Z7: 102.8 | AA7: 105.8 | AB7: 109.3 | AC7: 41426
A8: Rural+Urban | B8: 2013 | C8: July | D8: 114.8 | E8: 116.4 | F8: 111.9 | G8: 108.9 | H8: 104.3 | I8: 111.7 | J8: 140 | K8: 106.4 | L8: 103.3 | M8: 106.8 | N8: 109.6 | O8: 112.6 | P8: 110.3 | Q8: 110.2 | R8: 108.8 | S8: 107.7 | T8: 109.2 | U8: 108.2 | V8: 107 | W8: 107.1 | X8: 106.1 | Y8: 109.1 | Z8: 102.8 | AA8: 106.9 | AB8: 111 | AC8: 41456
A9: Rural+Urban | B9: 2013 | C9: August | D9: 115.6 | E9: 117.2 | F9: 111.7 | G9: 109.6 | H9: 104.5 | I9: 109.8 | J9: 151.8 | K9: 106.5 | L9: 103.1 | M9: 107.4 | N9: 110.2 | O9: 113.4 | P9: 111.2 | Q9: 111 | R9: 109.4 | S9: 108.9 | T9: 109.7 | U9: 108.7 | V9: 107.5 | W9: 108 | X9: 106.6 | Y9: 109.9 | Z9: 105.4 | AA9: 107.9 | AB9: 112.4 | AC9: 41487
A10: Rural+Urban | B10: 2013 | C10: September | D10: 116.4 | E10: 116.9 | F10: 112.3 | G10: 110.5 | H10: 105.3 | I10: 107.3 | J10: 160.9 | K10: 107.1 | L10: 103.1 | M10: 108.3 | N10: 110.7 | O10: 114.6 | P10: 112 | Q10: 112.2 | R10: 110.4 | S10: 109.7 | T10: 110.5 | U10: 109.6 | V10: 108.1 | W10: 109.9 | X10: 107.5 | Y10: 110.6 | Z10: 106.8 | AA10: 109 | AB10: 113.7 | AC10: 41518
A11: Rural+Urban | B11: 2013 | C11: October | D11: 117.1 | E11: 116.3 | F11: 113.3 | G11: 111.2 | H11: 105.7 | I11: 109.9 | J11: 171.2 | K11: 107.3 | L11: 102.7 | M11: 108.7 | N11: 111.2 | O11: 115.4 | P11: 112.5 | Q11: 113.2 | R11: 111.2 | S11: 110.5 | T11: 110.9 | U11: 110.3 | V11: 108.6 | W11: 109.5 | X11: 108.1 | Y11: 110.8 | Z11: 107.4 | AA11: 109.2 | AB11: 114.8 | AC11: 41548
A12: Rural+Urban | B12: 2013 | C12: November | D12: 118.1 | E12: 115.4 | F12: 118.7 | G12: 112.5 | H12: 106.8 | I12: 113.5 | J12: 183.1 | K12: 108.2 | L12: 102.2 | M12: 109.4 | N12: 111.8 | O12: 116.5 | P12: 113.1 | Q12: 114.2 | R12: 111.9 | S12: 111.1 | T12: 111.6 | U12: 111.1 | V12: 109.3 | W12: 109.5 | X12: 108.6 | Y12: 111.2 | Z12: 108.1 | AA12: 109.7 | AB12: 116.3 | AC12: 41579
A13: Rural+Urban | B13: 2013 | C13: December | D13: 119.1 | E13: 116.7 | F13: 123.5 | G13: 113.4 | H13: 107.3 | I13: 113.3 | J13: 145.4 | K13: 108.7 | L13: 101.5 | M13: 110.5 | N13: 112.1 | O13: 117.4 | P13: 114 | Q13: 115.2 | R13: 112.7 | S13: 110.7 | T13: 111.9 | U13: 111.7 | V13: 109.7 | W13: 109.8 | X13: 109 | Y13: 111.5 | Z13: 107.9 | AA13: 110 | AB13: 114.5 | AC13: 41609
A14: Rural+Urban | B14: 2014 | C14: January | D14: 119.6 | E14: 118.8 | F14: 124.1 | G14: 114.1 | H14: 106.8 | I14: 113.9 | J14: 122.2 | K14: 108.9 | L14: 100.2 | M14: 111 | N14: 112.3 | O14: 118.1 | P14: 114.5 | Q14: 115.8 | R14: 113.2 | S14: 111.6 | T14: 112.2 | U14: 112.3 | V14: 110.3 | W14: 110.7 | X14: 109.7 | Y14: 111.6 | Z14: 108.2 | AA14: 110.6 | AB14: 113.6 | AC14: 41640 | AD14: =((AB14-AB2)/AB2)*100 -> 8.6042065
A15: Rural+Urban | B15: 2014 | C15: February | D15: 120.2 | E15: 119.2 | F15: 122.5 | G15: 115.1 | H15: 106.6 | I15: 115.4 | J15: 114.5 | K15: 109.3 | L15: 99.2 | M15: 111.4 | N15: 112.6 | O15: 118.8 | P15: 114.7 | Q15: 116.4 | R15: 113.3 | S15: 112.5 | T15: 112.4 | U15: 112.8 | V15: 110.7 | W15: 111.1 | X15: 110.1 | Y15: 111.8 | Z15: 108.7 | AA15: 110.9 | AB15: 113.6 | AC15: 41671 | AD15: =((AB15-AB3)/AB3)*100 -> 7.8822412
A16: Rural+Urban | B16: 2014 | C16: March | D16: 120.7 | E16: 119.3 | F16: 121 | G16: 116.1 | H16: 106.9 | I16: 118.7 | J16: 116.3 | K16: 109.8 | L16: 99.6 | M16: 111.8 | N16: 112.7 | O16: 119.3 | P16: 115.2 | Q16: 116.8 | R16: 113.7 | S16: 113.2 | T16: 112.5 | U16: 113.2 | V16: 111.2 | W16: 111.4 | X16: 110.6 | Y16: 112 | Z16: 109 | AA16: 111.3 | AB16: 114.2 | AC16: 41699 | AD16: =((AB16-AB4)/AB4)*100 -> 8.2464455
A17: Rural+Urban | B17: 2014 | C17: April | D17: 120.9 | E17: 119.9 | F17: 116.2 | G17: 117 | H17: 107.3 | I17: 126.1 | J17: 120.7 | K17: 111 | L17: 101.8 | M17: 112.6 | N17: 113.2 | O17: 119.8 | P17: 116 | Q17: 117.4 | R17: 114.6 | S17: 113.9 | T17: 112.5 | U17: 113.6 | V17: 111.5 | W17: 111.2 | X17: 110.9 | Y17: 112.7 | Z17: 109 | AA17: 111.5 | AB17: 115.1 | AC17: 41730 | AD17: =((AB17-AB5)/AB5)*100 -> 8.4825636
A18: Rural+Urban | B18: 2014 | C18: May | D18: 121.1 | E18: 121.6 | F18: 115.9 | G18: 118.4 | H18: 107.7 | I18: 127.7 | J18: 125 | K18: 111.9 | L18: 102.8 | M18: 113.4 | N18: 113.7 | O18: 120.4 | P18: 116.8 | Q18: 118 | R18: 115.2 | S18: 114.3 | T18: 112.5 | U18: 114.1 | V18: 111.8 | W18: 111.3 | X18: 111.2 | Y18: 113 | Z18: 109.1 | AA18: 111.8 | AB18: 115.8 | AC18: 41760 | AD18: =((AB18-AB6)/AB6)*100 -> 8.3255379
A19: Rural+Urban | B19: 2014 | C19: June | D19: 121.5 | E19: 123.1 | F19: 115.8 | G19: 119.7 | H19: 107.8 | I19: 128.3 | J19: 132.1 | K19: 112.4 | L19: 102.9 | M19: 114.3 | N19: 114.2 | O19: 121.2 | P19: 117.8 | Q19: 118.8 | R19: 115.6 | S19: 113.9 | T19: 113.2 | U19: 114.6 | V19: 112.3 | W19: 111.8 | X19: 111.6 | Y19: 114.8 | Z19: 108.3 | AA19: 112.3 | AB19: 116.7 | AC19: 41791 | AD19: =((AB19-AB7)/AB7)*100 -> 6.7703568
A20: Rural+Urban | B20: 2014 | C20: July | D20: 122.4 | E20: 123.9 | F20: 117.8 | G20: 121 | H20: 107.9 | I20: 131.2 | J20: 157.7 | K20: 113.2 | L20: 104.1 | M20: 115.5 | N20: 114.8 | O20: 122.1 | P20: 118.8 | Q20: 119.6 | R20: 116.3 | S20: 114.8 | T20: 113.9 | U20: 115.2 | V20: 112.7 | W20: 113.1 | X20: 112.1 | Y20: 116.8 | Z20: 109.2 | AA20: 113.3 | AB20: 119.2 | AC20: 41821 | AD20: =((AB20-AB8)/AB8)*100 -> 7.3873874
A21: Rural+Urban | B21: 2014 | C21: August | D21: 122.7 | E21: 124.4 | F21: 117.3 | G21: 122 | H21: 108 | I21: 131.1 | J21: 168.2 | K21: 114.5 | L21: 104.3 | M21: 117.1 | N21: 115.2 | O21: 123.1 | P21: 119.9 | Q21: 120 | R21: 116.8 | S21: 115.5 | T21: 114 | U21: 115.6 | V21: 113.3 | W21: 112.8 | X21: 112.6 | Y21: 118 | Z21: 109.9 | AA21: 113.7 | AB21: 120.3 | AC21: 41852 | AD21: =((AB21-AB9)/AB9)*100 -> 7.0284698
A22: Rural+Urban | B22: 2014 | C22: September | D22: 122.9 | E22: 123.5 | F22: 117.3 | G22: 122.7 | H22: 107.9 | I22: 127.3 | J22: 162.1 | K22: 115.6 | L22: 103.8 | M22: 117.6 | N22: 115.8 | O22: 123.8 | P22: 120.8 | Q22: 120.7 | R22: 117.2 | S22: 116.1 | T22: 114.3 | U22: 116.1 | V22: 113.7 | W22: 112 | X22: 113.1 | Y22: 118.6 | Z22: 109.5 | AA22: 113.7 | AB22: 120.1 | AC22: 41883 | AD22: =((AB22-AB10)/AB10)*100 -> 5.6288478
A23: Rural+Urban | B23: 2014 | C23: October | D23: 123.2 | E23: 123.8 | F23: 118.1 | G23: 123.2 | H23: 107.9 | I23: 126.4 | J23: 156.8 | K23: 116.1 | L23: 103.1 | M23: 118.1 | N23: 116.1 | O23: 124.5 | P23: 121.1 | Q23: 121.5 | R23: 118.1 | S23: 116.7 | T23: 114.7 | U23: 116.7 | V23: 114.3 | W23: 111.8 | X23: 113.3 | Y23: 118.8 | Z23: 109.6 | AA23: 113.9 | AB23: 120.1 | AC23: 41913 | AD23: =((AB23-AB11)/AB11)*100 -> 4.6167247
A24: Rural+Urban | B24: 2014 | C24: November | D24: 123.3 | E24: 123.7 | F24: 121 | G24: 124.2 | H24: 107.8 | I24: 125.7 | J24: 152.4 | K24: 117.2 | L24: 102.1 | M24: 118.7 | N24: 116.4 | O24: 125.6 | P24: 122.1 | Q24: 122.1 | R24: 118.4 | S24: 117.1 | T24: 115.5 | U24: 117.3 | V24: 114.8 | W24: 110.8 | X24: 113.7 | Y24: 119 | Z24: 109.1 | AA24: 113.8 | AB24: 120.1 | AC24: 41944 | AD24: =((AB24-AB12)/AB12)*100 -> 3.2674119
A25: Rural+Urban | B25: 2014 | C25: December | D25: 122.9 | E25: 123.2 | F25: 123.5 | G25: 124.5 | H25: 107.6 | I25: 125.7 | J25: 140.5 | K25: 117.6 | L25: 100.6 | M25: 119.1 | N25: 116.8 | O25: 126.1 | P25: 123 | Q25: 122.6 | R25: 118.6 | S25: 116.5 | T25: 115.7 | U25: 117.5 | V25: 115.1 | W25: 110.1 | X25: 113.9 | Y25: 119.5 | Z25: 109.8 | AA25: 113.8 | AB25: 119.4 | AC25: 41974 | AD25: =((AB25-AB13)/AB13)*100 -> 4.279476
... A125: Rural+Urban | B125: 2023 | C125: May | D125: 173.7 | E125: 214.3 | F125: 173.2 | G125: 179.5 | H125: 170 | I125: 172.2 | J125: 161 | K125: 175.6 | L125: 122.7 | M125: 218 | N125: 173.4 | O125: 194.2 | P125: 201 | Q125: 187.3 | R125: 179.7 | S125: 175.6 | T125: 182.8 | U125: 175.2 | V125: 185.7 | W125: 164.8 | X125: 171.2 | Y125: 177.1 | Z125: 185.2 | AA125: 175.7 | AB125: 179.1 | AC125: 45047 | AD125: =((AB125-AB113)/AB113)*100 -> 4.3098427

Sheet Clean Data
A1: Sector | B1: Year | C1: Month | D1: Cereals and products | E1: Meat and fish | F1: Egg | G1: Milk and products | H1: Oils and fats | I1: Fruits | J1: Vegetables | K1: Pulses and products | L1: Sugar and Confectionery | M1: Spices | N1: Non-alcoholic beverages | O1: Prepared meals, snacks, sweets etc. | P1: Food and beverages | Q1: Pan, tobacco and intoxicants | R1: Clothing | S1: Footwear | T1: Clothing and footwear | U1: Housing | V1: Fuel and light | W1: Household goods and services | X1: Health | Y1: Transport and communication | Z1: Recreation and amusement | AA1: Education | AB1: Personal care and effects | AC1: Miscellaneous | AD1: General index | AE1: Month NO. | AF1: Date
A2: Rural | B2: 2013 | C2: January | D2: 107.5 | E2: 106.3 | F2: 108.1 | G2: 104.9 | H2: 106.1 | I2: 103.9 | J2: 101.9 | K2: 106.1 | L2: 106.8 | M2: 103.1 | N2: 104.8 | O2: 106.7 | P2: 105.5 | Q2: 105.1 | R2: 106.5 | S2: 105.8 | T2: 106.4 | U2: 139.2 | V2: 105.5 | W2: 104.8 | X2: 104 | Y2: 103.3 | Z2: 103.4 | AA2: 103.8 | AB2: 104.7 | AC2: 104 | AD2: 105.1 | AE2: =IF(C2="January",1,IF(C2="February",2,IF(C2="March",3,IF(C2="April",4,IF(C2="May",5,IF(C2="June",6,IF(C2="July",7,IF(C2="August",8,IF(C2="September",9,IF(C2="October",10,IF(C2="November",11,IF(C2="December",12,"")))))))))))) -> 1 | AF2: =DATE(B2,AE2,1) -> 41275
A3: Urban | B3: 2013 | C3: January | D3: 110.5 | E3: 109.1 | F3: 113 | G3: 103.6 | H3: 103.4 | I3: 102.3 | J3: 102.9 | K3: 105.8 | L3: 105.1 | M3: 101.8 | N3: 105.1 | O3: 107.9 | P3: 105.9 | Q3: 105.2 | R3: 105.9 | S3: 105 | T3: 105.8 | U3: 100.3 | V3: 105.4 | W3: 104.8 | X3: 104.1 | Y3: 103.2 | Z3: 102.9 | AA3: 103.5 | AB3: 104.3 | AC3: 103.7 | AD3: 104 | AE3: =IF(C3="January",1,IF(C3="February",2,IF(C3="March",3,IF(C3="April",4,IF(C3="May",5,IF(C3="June",6,IF(C3="July",7,IF(C3="August",8,IF(C3="September",9,IF(C3="October",10,IF(C3="November",11,IF(C3="December",12,"")))))))))))) -> 1 | AF3: =DATE(B3,AE3,1) -> 41275
A4: Rural+Urban | B4: 2013 | C4: January | D4: 108.4 | E4: 107.3 | F4: 110 | G4: 104.4 | H4: 105.1 | I4: 103.2 | J4: 102.2 | K4: 106 | L4: 106.2 | M4: 102.7 | N4: 104.9 | O4: 107.3 | P4: 105.6 | Q4: 105.1 | R4: 106.3 | S4: 105.5 | T4: 106.2 | U4: 100.3 | V4: 105.5 | W4: 104.8 | X4: 104 | Y4: 103.2 | Z4: 103.1 | AA4: 103.6 | AB4: 104.5 | AC4: 103.9 | AD4: 104.6 | AE4: =IF(C4="January",1,IF(C4="February",2,IF(C4="March",3,IF(C4="April",4,IF(C4="May",5,IF(C4="June",6,IF(C4="July",7,IF(C4="August",8,IF(C4="September",9,IF(C4="October",10,IF(C4="November",11,IF(C4="December",12,"")))))))))))) -> 1 | AF4: =DATE(B4,AE4,1) -> 41275
A5: Rural | B5: 2013 | C5: February | D5: 109.2 | E5: 108.7 | F5: 110.2 | G5: 105.4 | H5: 106.7 | I5: 104 | J5: 102.4 | K5: 105.9 | L5: 105.7 | M5: 103.1 | N5: 105.1 | O5: 107.7 | P5: 106.3 | Q5: 105.6 | R5: 107.1 | S5: 106.3 | T5: 107 | U5: 139.2 | V5: 106.2 | W5: 105.2 | X5: 104.4 | Y5: 103.9 | Z5: 104 | AA5: 104.1 | AB5: 104.6 | AC5: 104.4 | AD5: 105.8 | AE5: =IF(C5="January",1,IF(C5="February",2,IF(C5="March",3,IF(C5="April",4,IF(C5="May",5,IF(C5="June",6,IF(C5="July",7,IF(C5="August",8,IF(C5="September",9,IF(C5="October",10,IF(C5="November",11,IF(C5="December",12,"")))))))))))) -> 2 | AF5: =DATE(B5,AE5,1) -> 41306
A6: Urban | B6: 2013 | C6: February | D6: 112.9 | E6: 112.9 | F6: 116.9 | G6: 104 | H6: 103.5 | I6: 103.1 | J6: 104.9 | K6: 104.1 | L6: 103.8 | M6: 102.3 | N6: 106 | O6: 109 | P6: 107.2 | Q6: 106 | R6: 106.6 | S6: 105.5 | T6: 106.4 | U6: 100.4 | V6: 105.7 | W6: 105.2 | X6: 104.7 | Y6: 104.4 | Z6: 103.3 | AA6: 103.7 | AB6: 104.3 | AC6: 104.3 | AD6: 104.7 | AE6: =IF(C6="January",1,IF(C6="February",2,IF(C6="March",3,IF(C6="April",4,IF(C6="May",5,IF(C6="June",6,IF(C6="July",7,IF(C6="August",8,IF(C6="September",9,IF(C6="October",10,IF(C6="November",11,IF(C6="December",12,"")))))))))))) -> 2 | AF6: =DATE(B6,AE6,1) -> 41306
A7: Rural+Urban | B7: 2013 | C7: February | D7: 110.4 | E7: 110.2 | F7: 112.8 | G7: 104.9 | H7: 105.5 | I7: 103.6 | J7: 103.2 | K7: 105.3 | L7: 105.1 | M7: 102.8 | N7: 105.5 | O7: 108.3 | P7: 106.6 | Q7: 105.7 | R7: 106.9 | S7: 106 | T7: 106.8 | U7: 100.4 | V7: 106 | W7: 105.2 | X7: 104.5 | Y7: 104.2 | Z7: 103.6 | AA7: 103.9 | AB7: 104.5 | AC7: 104.4 | AD7: 105.3 | AE7: =IF(C7="January",1,IF(C7="February",2,IF(C7="March",3,IF(C7="April",4,IF(C7="May",5,IF(C7="June",6,IF(C7="July",7,IF(C7="August",8,IF(C7="September",9,IF(C7="October",10,IF(C7="November",11,IF(C7="December",12,"")))))))))))) -> 2 | AF7: =DATE(B7,AE7,1) -> 41306
A8: Rural | B8: 2013 | C8: March | D8: 110.2 | E8: 108.8 | F8: 109.9 | G8: 105.6 | H8: 106.2 | I8: 105.7 | J8: 101.4 | K8: 105.7 | L8: 105 | M8: 103.3 | N8: 105.6 | O8: 108.2 | P8: 106.6 | Q8: 106.5 | R8: 107.6 | S8: 106.8 | T8: 107.5 | U8: 139.2 | V8: 106.1 | W8: 105.6 | X8: 104.7 | Y8: 104.6 | Z8: 104 | AA8: 104.3 | AB8: 104.3 | AC8: 104.6 | AD8: 106 | AE8: =IF(C8="January",1,IF(C8="February",2,IF(C8="March",3,IF(C8="April",4,IF(C8="May",5,IF(C8="June",6,IF(C8="July",7,IF(C8="August",8,IF(C8="September",9,IF(C8="October",10,IF(C8="November",11,IF(C8="December",12,"")))))))))))) -> 3 | AF8: =DATE(B8,AE8,1) -> 41334
A9: Urban | B9: 2013 | C9: March | D9: 113.9 | E9: 111.4 | F9: 113.2 | G9: 104.3 | H9: 102.7 | I9: 104.9 | J9: 103.8 | K9: 103.5 | L9: 102.6 | M9: 102.4 | N9: 107 | O9: 109.8 | P9: 107.3 | Q9: 106.8 | R9: 107.2 | S9: 106 | T9: 107 | U9: 100.4 | V9: 106 | W9: 105.7 | X9: 105.2 | Y9: 105.5 | Z9: 103.5 | AA9: 103.8 | AB9: 104.2 | AC9: 104.9 | AD9: 105 | AE9: =IF(C9="January",1,IF(C9="February",2,IF(C9="March",3,IF(C9="April",4,IF(C9="May",5,IF(C9="June",6,IF(C9="July",7,IF(C9="August",8,IF(C9="September",9,IF(C9="October",10,IF(C9="November",11,IF(C9="December",12,"")))))))))))) -> 3 | AF9: =DATE(B9,AE9,1) -> 41334
A10: Rural+Urban | B10: 2013 | C10: March | D10: 111.4 | E10: 109.7 | F10: 111.2 | G10: 105.1 | H10: 104.9 | I10: 105.3 | J10: 102.2 | K10: 105 | L10: 104.2 | M10: 103 | N10: 106.2 | O10: 108.9 | P10: 106.9 | Q10: 106.6 | R10: 107.4 | S10: 106.5 | T10: 107.3 | U10: 100.4 | V10: 106.1 | W10: 105.6 | X10: 104.9 | Y10: 105.1 | Z10: 103.7 | AA10: 104 | AB10: 104.3 | AC10: 104.7 | AD10: 105.5 | AE10: =IF(C10="January",1,IF(C10="February",2,IF(C10="March",3,IF(C10="April",4,IF(C10="May",5,IF(C10="June",6,IF(C10="July",7,IF(C10="August",8,IF(C10="September",9,IF(C10="October",10,IF(C10="November",11,IF(C10="December",12,"")))))))))))) -> 3 | AF10: =DATE(B10,AE10,1) -> 41334
A11: Rural | B11: 2013 | C11: April | D11: 110.2 | E11: 109.5 | F11: 106.9 | G11: 106.3 | H11: 105.7 | I11: 108.3 | J11: 103.4 | K11: 105.7 | L11: 104.2 | M11: 103.2 | N11: 106.5 | O11: 108.8 | P11: 107.1 | Q11: 107.1 | R11: 108.1 | S11: 107.4 | T11: 108 | U11: 139.2 | V11: 106.5 | W11: 106.1 | X11: 105.1 | Y11: 104.4 | Z11: 104.5 | AA11: 104.8 | AB11: 102.7 | AC11: 104.6 | AD11: 106.4 | AE11: =IF(C11="January",1,IF(C11="February",2,IF(C11="March",3,IF(C11="April",4,IF(C11="May",5,IF(C11="June",6,IF(C11="July",7,IF(C11="August",8,IF(C11="September",9,IF(C11="October",10,IF(C11="November",11,IF(C11="December",12,"")))))))))))) -> 4 | AF11: =DATE(B11,AE11,1) -> 41365
A12: Urban | B12: 2013 | C12: April | D12: 114.6 | E12: 113.4 | F12: 106 | G12: 104.7 | H12: 102.1 | I12: 109.5 | J12: 109.7 | K12: 104.6 | L12: 102 | M12: 103.5 | N12: 108.2 | O12: 110.6 | P12: 108.8 | Q12: 108.5 | R12: 107.9 | S12: 106.4 | T12: 107.7 | U12: 100.5 | V12: 106.4 | W12: 106.5 | X12: 105.7 | Y12: 105 | Z12: 104 | AA12: 105.2 | AB12: 103.2 | AC12: 105.1 | AD12: 105.7 | AE12: =IF(C12="January",1,IF(C12="February",2,IF(C12="March",3,IF(C12="April",4,IF(C12="May",5,IF(C12="June",6,IF(C12="July",7,IF(C12="August",8,IF(C12="September",9,IF(C12="October",10,IF(C12="November",11,IF(C12="December",12,"")))))))))))) -> 4 | AF12: =DATE(B12,AE12,1) -> 41365
A13: Rural+Urban | B13: 2013 | C13: April | D13: 111.6 | E13: 110.9 | F13: 106.6 | G13: 105.7 | H13: 104.4 | I13: 108.9 | J13: 105.5 | K13: 105.3 | L13: 103.5 | M13: 103.3 | N13: 107.2 | O13: 109.6 | P13: 107.7 | Q13: 107.5 | R13: 108 | S13: 107 | T13: 107.9 | U13: 100.5 | V13: 106.5 | W13: 106.3 | X13: 105.3 | Y13: 104.7 | Z13: 104.2 | AA13: 105 | AB13: 102.9 | AC13: 104.8 | AD13: 106.1 | AE13: =IF(C13="January",1,IF(C13="February",2,IF(C13="March",3,IF(C13="April",4,IF(C13="May",5,IF(C13="June",6,IF(C13="July",7,IF(C13="August",8,IF(C13="September",9,IF(C13="October",10,IF(C13="November",11,IF(C13="December",12,"")))))))))))) -> 4 | AF13: =DATE(B13,AE13,1) -> 41365
... A31: Rural+Urban | B31: 2013 | C31: October | D31: 117.1 | E31: 116.3 | F31: 113.3 | G31: 111.2 | H31: 105.7 | I31: 109.9 | J31: 171.2 | K31: 107.3 | L31: 102.7 | M31: 108.7 | N31: 111.2 | O31: 115.4 | P31: 120.2 | Q31: 112.5 | R31: 113.2 | S31: 111.2 | T31: 112.8 | U31: 110.5 | V31: 110.9 | W31: 110.3 | X31: 108.6 | Y31: 109.5 | Z31: 108.1 | AA31: 110.8 | AB31: 107.4 | AC31: 109.2 | AD31: 114.8 | AE31: =IF(C31="January",1,IF(C31="February",2,IF(C31="March",3,IF(C31="April",4,IF(C31="May",5,IF(C31="June",6,IF(C31="July",7,IF(C31="August",8,IF(C31="September",9,IF(C31="October",10,IF(C31="November",11,IF(C31="December",12,"")))))))))))) -> 10 | AF31: =DATE(B31,AE31,1) -> 41548
A32: Rural | B32: 2013 | C32: November | D32: 117.3 | E32: 114.9 | F32: 116.2 | G32: 112.8 | H32: 108.9 | I32: 116.6 | J32: 178.1 | K32: 109.1 | L32: 103.6 | M32: 109 | N32: 111.8 | O32: 116 | P32: 122.5 | Q32: 112.8 | R32: 114.6 | S32: 113.1 | T32: 114.4 | U32: 139.2 | V32: 112.6 | W32: 111.3 | X32: 109.7 | Y32: 109.6 | Z32: 108.7 | AA32: 111 | AB32: 108.2 | AC32: 109.8 | AD32: 117.4 | AE32: 11 | AF32: =DATE(B32,AE32,1) -> 41579
A33: Urban | B33: 2013 | C33: November | D33: 119.8 | E33: 116.3 | F33: 122.6 | G33: 112 | H33: 103.2 | I33: 110 | J33: 192.8 | K33: 106.3 | L33: 99.5 | M33: 110.3 | N33: 111.8 | O33: 117.1 | P33: 122.9 | Q33: 114.1 | R33: 113.5 | S33: 110.3 | T33: 113 | U33: 111.1 | V33: 110 | W33: 110.9 | X33: 108.6 | Y33: 109.5 | Z33: 108.5 | AA33: 111.3 | AB33: 107.9 | AC33: 109.6 | AD33: 115 | AE33: =IF(C33="January",1,IF(C33="February",2,IF(C33="March",3,IF(C33="April",4,IF(C33="May",5,IF(C33="June",6,IF(C33="July",7,IF(C33="August",8,IF(C33="September",9,IF(C33="October",10,IF(C33="November",11,IF(C33="December",12,"")))))))))))) -> 11 | AF33: =DATE(B33,AE33,1) -> 41579
A34: Rural+Urban | B34: 2013 | C34: November | D34: 118.1 | E34: 115.4 | F34: 118.7 | G34: 112.5 | H34: 106.8 | I34: 113.5 | J34: 183.1 | K34: 108.2 | L34: 102.2 | M34: 109.4 | N34: 111.8 | O34: 116.5 | P34: 122.6 | Q34: 113.1 | R34: 114.2 | S34: 111.9 | T34: 113.8 | U34: 111.1 | V34: 111.6 | W34: 111.1 | X34: 109.3 | Y34: 109.5 | Z34: 108.6 | AA34: 111.2 | AB34: 108.1 | AC34: 109.7 | AD34: 116.3 | AE34: =IF(C34="January",1,IF(C34="February",2,IF(C34="March",3,IF(C34="April",4,IF(C34="May",5,IF(C34="June",6,IF(C34="July",7,IF(C34="August",8,IF(C34="September",9,IF(C34="October",10,IF(C34="November",11,IF(C34="December",12,"")))))))))))) -> 11 | AF34: =DATE(B34,AE34,1) -> 41579
A35: Rural | B35: 2013 | C35: December | D35: 118.4 | E35: 115.9 | F35: 120.4 | G35: 113.8 | H35: 109.5 | I35: 115.5 | J35: 145.7 | K35: 109.5 | L35: 102.9 | M35: 109.8 | N35: 112.1 | O35: 116.8 | P35: 118.7 | Q35: 113.6 | R35: 115.8 | S35: 114 | T35: 115.5 | U35: 139.2 | V35: 112.8 | W35: 112.1 | X35: 110.1 | Y35: 109.9 | Z35: 109.2 | AA35: 111.6 | AB35: 108.1 | AC35: 110.1 | AD35: 115.5 | AE35: =IF(C35="January",1,IF(C35="February",2,IF(C35="March",3,IF(C35="April",4,IF(C35="May",5,IF(C35="June",6,IF(C35="July",7,IF(C35="August",8,IF(C35="September",9,IF(C35="October",10,IF(C35="November",11,IF(C35="December",12,"")))))))))))) -> 12 | AF35: =DATE(B35,AE35,1) -> 41609
A36: Urban | B36: 2013 | C36: December | D36: 120.5 | E36: 118.1 | F36: 128.5 | G36: 112.8 | H36: 103.4 | I36: 110.7 | J36: 144.8 | K36: 107.1 | L36: 98.6 | M36: 111.9 | N36: 112.1 | O36: 118.1 | P36: 117.8 | Q36: 115 | R36: 114.2 | S36: 110.9 | T36: 113.7 | U36: 110.7 | V36: 110.4 | W36: 111.3 | X36: 109 | Y36: 109.7 | Z36: 108.9 | AA36: 111.4 | AB36: 107.7 | AC36: 109.8 | AD36: 113.3 | AE36: =IF(C36="January",1,IF(C36="February",2,IF(C36="March",3,IF(C36="April",4,IF(C36="May",5,IF(C36="June",6,IF(C36="July",7,IF(C36="August",8,IF(C36="September",9,IF(C36="October",10,IF(C36="November",11,IF(C36="December",12,"")))))))))))) -> 12 | AF36: =DATE(B36,AE36,1) -> 41609
A37: Rural+Urban | B37: 2013 | C37: December | D37: 119.1 | E37: 116.7 | F37: 123.5 | G37: 113.4 | H37: 107.3 | I37: 113.3 | J37: 145.4 | K37: 108.7 | L37: 101.5 | M37: 110.5 | N37: 112.1 | O37: 117.4 | P37: 118.4 | Q37: 114 | R37: 115.2 | S37: 112.7 | T37: 114.8 | U37: 110.7 | V37: 111.9 | W37: 111.7 | X37: 109.7 | Y37: 109.8 | Z37: 109 | AA37: 111.5 | AB37: 107.9 | AC37: 110 | AD37: 114.5 | AE37: =IF(C37="January",1,IF(C37="February",2,IF(C37="March",3,IF(C37="April",4,IF(C37="May",5,IF(C37="June",6,IF(C37="July",7,IF(C37="August",8,IF(C37="September",9,IF(C37="October",10,IF(C37="November",11,IF(C37="December",12,"")))))))))))) -> 12 | AF37: =DATE(B37,AE37,1) -> 41609
A38: Rural | B38: 2014 | C38: January | D38: 118.9 | E38: 117.1 | F38: 120.5 | G38: 114.4 | H38: 109 | I38: 115.5 | J38: 123.9 | K38: 109.6 | L38: 101.8 | M38: 110.2 | N38: 112.4 | O38: 117.3 | P38: 116 | Q38: 114 | R38: 116.5 | S38: 114.5 | T38: 116.2 | U38: 139.2 | V38: 113 | W38: 112.6 | X38: 110.6 | Y38: 110.5 | Z38: 109.6 | AA38: 111.8 | AB38: 108.3 | AC38: 110.6 | AD38: 114.2 | AE38: =IF(C38="January",1,IF(C38="February",2,IF(C38="March",3,IF(C38="April",4,IF(C38="May",5,IF(C38="June",6,IF(C38="July",7,IF(C38="August",8,IF(C38="September",9,IF(C38="October",10,IF(C38="November",11,IF(C38="December",12,"")))))))))))) -> 1 | AF38: =DATE(B38,AE38,1) -> 41640
A39: Urban | B39: 2014 | C39: January | D39: 121.2 | E39: 122 | F39: 129.9 | G39: 113.6 | H39: 102.9 | I39: 112.1 | J39: 118.9 | K39: 107.5 | L39: 96.9 | M39: 112.7 | N39: 112.1 | O39: 119 | P39: 115.5 | Q39: 115.7 | R39: 114.8 | S39: 111.3 | T39: 114.3 | U39: 111.6 | V39: 111 | W39: 111.9 | X39: 109.7 | Y39: 110.8 | Z39: 109.8 | AA39: 111.5 | AB39: 108 | AC39: 110.5 | AD39: 112.9 | AE39: =IF(C39="January",1,IF(C39="February",2,IF(C39="March",3,IF(C39="April",4,IF(C39="May",5,IF(C39="June",6,IF(C39="July",7,IF(C39="August",8,IF(C39="September",9,IF(C39="October",10,IF(C39="November",11,IF(C39="December",12,"")))))))))))) -> 1 | AF39: =DATE(B39,AE39,1) -> 41640
A40: Rural+Urban | B40: 2014 | C40: January | D40: 119.6 | E40: 118.8 | F40: 124.1 | G40: 114.1 | H40: 106.8 | I40: 113.9 | J40: 122.2 | K40: 108.9 | L40: 100.2 | M40: 111 | N40: 112.3 | O40: 118.1 | P40: 115.8 | Q40: 114.5 | R40: 115.8 | S40: 113.2 | T40: 115.4 | U40: 111.6 | V40: 112.2 | W40: 112.3 | X40: 110.3 | Y40: 110.7 | Z40: 109.7 | AA40: 111.6 | AB40: 108.2 | AC40: 110.6 | AD40: 113.6 | AE40: =IF(C40="January",1,IF(C40="February",2,IF(C40="March",3,IF(C40="April",4,IF(C40="May",5,IF(C40="June",6,IF(C40="July",7,IF(C40="August",8,IF(C40="September",9,IF(C40="October",10,IF(C40="November",11,IF(C40="December",12,"")))))))))))) -> 1 | AF40: =DATE(B40,AE40,1) -> 41640
A41: Rural | B41: 2014 | C41: February | D41: 119.4 | E41: 117.7 | F41: 121.2 | G41: 115 | H41: 109 | I41: 116.6 | J41: 116 | K41: 109.8 | L41: 101.1 | M41: 110.4 | N41: 112.9 | O41: 117.8 | P41: 115.3 | Q41: 114.2 | R41: 117.1 | S41: 114.5 | T41: 116.7 | U41: 139.2 | V41: 113.2 | W41: 112.9 | X41: 110.9 | Y41: 110.8 | Z41: 109.9 | AA41: 112 | AB41: 108.7 | AC41: 110.9 | AD41: 114 | AE41: =IF(C41="January",1,IF(C41="February",2,IF(C41="March",3,IF(C41="April",4,IF(C41="May",5,IF(C41="June",6,IF(C41="July",7,IF(C41="August",8,IF(C41="September",9,IF(C41="October",10,IF(C41="November",11,IF(C41="December",12,"")))))))))))) -> 2 | AF41: =DATE(B41,AE41,1) -> 41671
A42: Urban | B42: 2014 | C42: February | D42: 121.9 | E42: 122 | F42: 124.5 | G42: 115.2 | H42: 102.5 | I42: 114.1 | J42: 111.5 | K42: 108.2 | L42: 95.4 | M42: 113.5 | N42: 112.1 | O42: 119.9 | P42: 115.2 | Q42: 116.2 | R42: 115.3 | S42: 111.7 | T42: 114.7 | U42: 112.5 | V42: 111.1 | W42: 112.6 | X42: 110.4 | Y42: 111.3 | Z42: 110.3 | AA42: 111.6 | AB42: 108.7 | AC42: 111 | AD42: 113.1 | AE42: =IF(C42="January",1,IF(C42="February",2,IF(C42="March",3,IF(C42="April",4,IF(C42="May",5,IF(C42="June",6,IF(C42="July",7,IF(C42="August",8,IF(C42="September",9,IF(C42="October",10,IF(C42="November",11,IF(C42="December",12,"")))))))))))) -> 2 | AF42: =DATE(B42,AE42,1) -> 41671
A43: Rural+Urban | B43: 2014 | C43: February | D43: 120.2 | E43: 119.2 | F43: 122.5 | G43: 115.1 | H43: 106.6 | I43: 115.4 | J43: 114.5 | K43: 109.3 | L43: 99.2 | M43: 111.4 | N43: 112.6 | O43: 118.8 | P43: 115.3 | Q43: 114.7 | R43: 116.4 | S43: 113.3 | T43: 115.9 | U43: 112.5 | V43: 112.4 | W43: 112.8 | X43: 110.7 | Y43: 111.1 | Z43: 110.1 | AA43: 111.8 | AB43: 108.7 | AC43: 110.9 | AD43: 113.6 | AE43: =IF(C43="January",1,IF(C43="February",2,IF(C43="March",3,IF(C43="April",4,IF(C43="May",5,IF(C43="June",6,IF(C43="July",7,IF(C43="August",8,IF(C43="September",9,IF(C43="October",10,IF(C43="November",11,IF(C43="December",12,"")))))))))))) -> 2 | AF43: =DATE(B43,AE43,1) -> 41671
A44: Rural | B44: 2014 | C44: March | D44: 120.1 | E44: 118.1 | F44: 120.7 | G44: 116.1 | H44: 109.3 | I44: 119.6 | J44: 117.9 | K44: 110.2 | L44: 101.2 | M44: 110.7 | N44: 113 | O44: 118.3 | P44: 116.2 | Q44: 114.6 | R44: 117.5 | S44: 114.9 | T44: 117.2 | U44: 139.2 | V44: 113.4 | W44: 113.4 | X44: 111.4 | Y44: 111.2 | Z44: 110.2 | AA44: 112.4 | AB44: 108.9 | AC44: 111.3 | AD44: 114.6 | AE44: =IF(C44="January",1,IF(C44="February",2,IF(C44="March",3,IF(C44="April",4,IF(C44="May",5,IF(C44="June",6,IF(C44="July",7,IF(C44="August",8,IF(C44="September",9,IF(C44="October",10,IF(C44="November",11,IF(C44="December",12,"")))))))))))) -> 3 | AF44: =DATE(B44,AE44,1) -> 41699
... A373: Rural+Urban | B373: 2023 | C373: May | D373: 173.7 | E373: 214.3 | F373: 173.2 | G373: 179.5 | H373: 170 | I373: 172.2 | J373: 161 | K373: 175.6 | L373: 122.7 | M373: 218 | N373: 173.4 | O373: 194.2 | P373: 179.1 | Q373: 201 | R373: 187.3 | S373: 179.7 | T373: 186.2 | U373: 175.6 | V373: 182.8 | W373: 175.2 | X373: 185.7 | Y373: 164.8 | Z373: 171.2 | AA373: 177.1 | AB373: 185.2 | AC373: 175.7 | AD373: 179.1 | AE373: =IF(C373="January",1,IF(C373="February",2,IF(C373="March",3,IF(C373="April",4,IF(C373="May",5,IF(C373="June",6,IF(C373="July",7,IF(C373="August",8,IF(C373="September",9,IF(C373="October",10,IF(C373="November",11,IF(C373="December",12,"")))))))))))) -> 5 | AF373: =DATE(B373,AE373,1) -> 45047

Sheet Rural+Urban
A1: Sector | B1: Cereals and products | C1: Meat and fish | D1: Egg | E1: Milk and products | F1: Oils and fats | G1: Fruits | H1: Vegetables | I1: Pulses and products | J1: Sugar and Confectionery | K1: Spices | L1: Non-alcoholic beverages | M1: Prepared meals, snacks, sweets etc. | N1: Food and beverages | O1: Pan, tobacco and intoxicants | P1: Clothing | Q1: Footwear | R1: Clothing and footwear | S1: Housing | T1: Fuel and light | U1: Household goods and services | V1: Health | W1: Transport and communication | X1: Recreation and amusement | Y1: Education | Z1: Personal care and effects | AA1: Miscellaneous | AB1: General index | AC1: Month NO. | AD1: Date
A2: Rural+Urban | B2: 108.4 | C2: 107.3 | D2: 110 | E2: 104.4 | F2: 105.1 | G2: 103.2 | H2: 102.2 | I2: 106 | J2: 106.2 | K2: 102.7 | L2: 104.9 | M2: 107.3 | N2: 105.6 | O2: 105.1 | P2: 106.3 | Q2: 105.5 | R2: 106.2 | S2: 100.3 | T2: 105.5 | U2: 104.8 | V2: 104 | W2: 103.2 | X2: 103.1 | Y2: 103.6 | Z2: 104.5 | AA2: 103.9 | AB2: 104.6 | AC2: 1 | AD2: 41275
A3: Rural+Urban | B3: 110.4 | C3: 110.2 | D3: 112.8 | E3: 104.9 | F3: 105.5 | G3: 103.6 | H3: 103.2 | I3: 105.3 | J3: 105.1 | K3: 102.8 | L3: 105.5 | M3: 108.3 | N3: 106.6 | O3: 105.7 | P3: 106.9 | Q3: 106 | R3: 106.8 | S3: 100.4 | T3: 106 | U3: 105.2 | V3: 104.5 | W3: 104.2 | X3: 103.6 | Y3: 103.9 | Z3: 104.5 | AA3: 104.4 | AB3: 105.3 | AC3: 2 | AD3: 41306
A4: Rural+Urban | B4: 111.4 | C4: 109.7 | D4: 111.2 | E4: 105.1 | F4: 104.9 | G4: 105.3 | H4: 102.2 | I4: 105 | J4: 104.2 | K4: 103 | L4: 106.2 | M4: 108.9 | N4: 106.9 | O4: 106.6 | P4: 107.4 | Q4: 106.5 | R4: 107.3 | S4: 100.4 | T4: 106.1 | U4: 105.6 | V4: 104.9 | W4: 105.1 | X4: 103.7 | Y4: 104 | Z4: 104.3 | AA4: 104.7 | AB4: 105.5 | AC4: 3 | AD4: 41334
A5: Rural+Urban | B5: 111.6 | C5: 110.9 | D5: 106.6 | E5: 105.7 | F5: 104.4 | G5: 108.9 | H5: 105.5 | I5: 105.3 | J5: 103.5 | K5: 103.3 | L5: 107.2 | M5: 109.6 | N5: 107.7 | O5: 107.5 | P5: 108 | Q5: 107 | R5: 107.9 | S5: 100.5 | T5: 106.5 | U5: 106.3 | V5: 105.3 | W5: 104.7 | X5: 104.2 | Y5: 105 | Z5: 102.9 | AA5: 104.8 | AB5: 106.1 | AC5: 4 | AD5: 41365
A6: Rural+Urban | B6: 112.3 | C6: 111.3 | D6: 104.7 | E6: 106.8 | F6: 103.9 | G6: 109.3 | H6: 112.9 | I6: 105.8 | J6: 103.1 | K6: 104.3 | L6: 108.1 | M6: 110.5 | N6: 109.2 | O6: 108.6 | P6: 108.7 | Q6: 107.4 | R6: 108.5 | S6: 100.5 | T6: 107.4 | U6: 106.9 | V6: 105.9 | W6: 104 | X6: 104.8 | Y6: 105.6 | Z6: 102.3 | AA6: 104.8 | AB6: 106.9 | AC6: 5 | AD6: 41395
A7: Rural+Urban | B7: 113.8 | C7: 114.9 | D7: 109.8 | E7: 107.9 | F7: 104.2 | G7: 110.7 | H7: 126.7 | I7: 106.3 | J7: 103.2 | K7: 105.7 | L7: 109 | M7: 111.6 | N7: 112.2 | O7: 109.5 | P7: 109.5 | Q7: 108.1 | R7: 109.3 | S7: 106.6 | T7: 108.3 | U7: 107.6 | V7: 106.4 | W7: 105.1 | X7: 105.4 | Y7: 107.4 | Z7: 102.8 | AA7: 105.8 | AB7: 109.3 | AC7: 6 | AD7: 41426
A8: Rural+Urban | B8: 114.8 | C8: 116.4 | D8: 111.9 | E8: 108.9 | F8: 104.3 | G8: 111.7 | H8: 140 | I8: 106.4 | J8: 103.3 | K8: 106.8 | L8: 109.6 | M8: 112.6 | N8: 114.7 | O8: 110.3 | P8: 110.2 | Q8: 108.8 | R8: 110 | S8: 107.7 | T8: 109.2 | U8: 108.2 | V8: 107 | W8: 107.1 | X8: 106.1 | Y8: 109.1 | Z8: 102.8 | AA8: 106.9 | AB8: 111 | AC8: 7 | AD8: 41456
A9: Rural+Urban | B9: 115.6 | C9: 117.2 | D9: 111.7 | E9: 109.6 | F9: 104.5 | G9: 109.8 | H9: 151.8 | I9: 106.5 | J9: 103.1 | K9: 107.4 | L9: 110.2 | M9: 113.4 | N9: 116.6 | O9: 111.2 | P9: 111 | Q9: 109.4 | R9: 110.7 | S9: 108.9 | T9: 109.7 | U9: 108.7 | V9: 107.5 | W9: 108 | X9: 106.6 | Y9: 109.9 | Z9: 105.4 | AA9: 107.9 | AB9: 112.4 | AC9: 8 | AD9: 41487
A10: Rural+Urban | B10: 116.4 | C10: 116.9 | D10: 112.3 | E10: 110.5 | F10: 105.3 | G10: 107.3 | H10: 160.9 | I10: 107.1 | J10: 103.1 | K10: 108.3 | L10: 110.7 | M10: 114.6 | N10: 118.3 | O10: 112 | P10: 112.2 | Q10: 110.4 | R10: 111.9 | S10: 109.7 | T10: 110.5 | U10: 109.6 | V10: 108.1 | W10: 109.9 | X10: 107.5 | Y10: 110.6 | Z10: 106.8 | AA10: 109 | AB10: 113.7 | AC10: 9 | AD10: 41518
A11: Rural+Urban | B11: 117.1 | C11: 116.3 | D11: 113.3 | E11: 111.2 | F11: 105.7 | G11: 109.9 | H11: 171.2 | I11: 107.3 | J11: 102.7 | K11: 108.7 | L11: 111.2 | M11: 115.4 | N11: 120.2 | O11: 112.5 | P11: 113.2 | Q11: 111.2 | R11: 112.8 | S11: 110.5 | T11: 110.9 | U11: 110.3 | V11: 108.6 | W11: 109.5 | X11: 108.1 | Y11: 110.8 | Z11: 107.4 | AA11: 109.2 | AB11: 114.8 | AC11: 10 | AD11: 41548
A12: Rural+Urban | B12: 118.1 | C12: 115.4 | D12: 118.7 | E12: 112.5 | F12: 106.8 | G12: 113.5 | H12: 183.1 | I12: 108.2 | J12: 102.2 | K12: 109.4 | L12: 111.8 | M12: 116.5 | N12: 122.6 | O12: 113.1 | P12: 114.2 | Q12: 111.9 | R12: 113.8 | S12: 111.1 | T12: 111.6 | U12: 111.1 | V12: 109.3 | W12: 109.5 | X12: 108.6 | Y12: 111.2 | Z12: 108.1 | AA12: 109.7 | AB12: 116.3 | AC12: 11 | AD12: 41579
A13: Rural+Urban | B13: 119.1 | C13: 116.7 | D13: 123.5 | E13: 113.4 | F13: 107.3 | G13: 113.3 | H13: 145.4 | I13: 108.7 | J13: 101.5 | K13: 110.5 | L13: 112.1 | M13: 117.4 | N13: 118.4 | O13: 114 | P13: 115.2 | Q13: 112.7 | R13: 114.8 | S13: 110.7 | T13: 111.9 | U13: 111.7 | V13: 109.7 | W13: 109.8 | X13: 109 | Y13: 111.5 | Z13: 107.9 | AA13: 110 | AB13: 114.5 | AC13: 12 | AD13: 41609
... A125: Rural+Urban | B125: 173.7 | C125: 214.3 | D125: 173.2 | E125: 179.5 | F125: 170 | G125: 172.2 | H125: 161 | I125: 175.6 | J125: 122.7 | K125: 218 | L125: 173.4 | M125: 194.2 | N125: 179.1 | O125: 201 | P125: 187.3 | Q125: 179.7 | R125: 186.2 | S125: 175.6 | T125: 182.8 | U125: 175.2 | V125: 185.7 | W125: 164.8 | X125: 171.2 | Y125: 177.1 | Z125: 185.2 | AA125: 175.7 | AB125: 179.1 | AC125: 5 | AD125: 45047

Sheet Q1_Basket_Contribution
A1: Latest Month Contribution Using Equal-Weight Board Bucket
A2: Board buckets | B2: Broader buckets2 | C2: Contribution | E2: Sector | F2: Cereals and products | G2: Meat and fish | H2: Egg | I2: Milk and products | J2: Oils and fats | K2: Fruits | L2: Vegetables | M2: Pulses and products | N2: Sugar and Confectionery | O2: Spices | P2: Non-alcoholic beverages | Q2: Prepared meals, snacks, sweets etc. | R2: Food and beverages | S2: Pan, tobacco and intoxicants | T2: Clothing | U2: Footwear | V2: Clothing and footwear | W2: Housing | X2: Fuel and light | Y2: Household goods and services | Z2: Health | AA2: Transport and communication | AB2: Recreation and amusement | AC2: Education | AD2: Personal care and effects | AE2: Miscellaneous | AF2: General index | AG2: Month NO. | AH2: Date
A3: Food | B3: =AVERAGE(F3:Q3) -> 177.31667 | C3: =B3/$B$14 -> 0.089510172 | E3: Rural+Urban | F3: 173.7 | G3: 214.3 | H3: 173.2 | I3: 179.5 | J3: 170 | K3: 172.2 | L3: 161 | M3: 175.6 | N3: 122.7 | O3: 218 | P3: 173.4 | Q3: 194.2 | R3: 179.1 | S3: 201 | T3: 187.3 | U3: 179.7 | V3: 186.2 | W3: 175.6 | X3: 182.8 | Y3: 175.2 | Z3: 185.7 | AA3: 164.8 | AB3: 171.2 | AC3: 177.1 | AD3: 185.2 | AE3: 175.7 | AF3: 179.1 | AG3: 5 | AH3: 45047
A4: Pan/Tabacco | B4: =S3 -> 201 | C4: =B4/$B$14 -> 0.10146561
A5: Clothing | B5: =AVERAGE(T3:U3) -> 183.5 | C5: =B5/$B$14 -> 0.092631544
A6: Housing | B6: =W3 -> 175.6 | C6: =B6/$B$14 -> 0.088643592
A7: Energy | B7: =X3 -> 182.8 | C7: =B7/$B$14 -> 0.092278181
A8: Household | B8: =Y3 -> 175.2 | C8: =B8/$B$14 -> 0.08844167
A9: Health | B9: =Z3 -> 185.7 | C9: =B9/$B$14 -> 0.093742112
A10: Transport | B10: =AA3 -> 164.8 | C10: =B10/$B$14 -> 0.083191708
A11: Education/Recreation | B11: =AVERAGE(AB3:AC3) -> 174.15 | C11: =B11/$B$14 -> 0.087911626
A12: Personal Care | B12: =AD3 -> 185.2 | C12: =B12/$B$14 -> 0.09348971
A13: Miscellaneous | B13: =AE3 -> 175.7 | C13: =B13/$B$14 -> 0.088694072
A14: Sum | B14: =SUM(B3:B13) -> 1980.9667

Sheet Q2_YoY Trend
A1: Sector | B1: Year | C1: General index | D1: Date | E1: Genearl YoY% | F1: year | G1: Avg YoY%
A2: Rural+Urban | B2: 2017 | C2: 130.3 | D2: 42736 | E2: 3.1670625 | F2: 2017 | G2: =AVERAGEIFS($E:$E,$B:$B,'Q2_YoY Trend'!F2) -> 3.3273885 | I2: 2022 Shows the Highest Average Inflation in the Analysis period
A3: Rural+Urban | B3: 2017 | C3: 130.6 | D3: 42767 | E3: 3.6507937 | F3: 2018 | G3: =AVERAGEIFS($E:$E,$B:$B,'Q2_YoY Trend'!F3) -> 3.9676972
A4: Rural+Urban | B4: 2017 | C4: 130.9 | D4: 42795 | E4: 3.8888889 | F4: 2019 | G4: =AVERAGEIFS($E:$E,$B:$B,'Q2_YoY Trend'!F4) -> 3.972956
A5: Rural+Urban | B5: 2017 | C5: 131.1 | D5: 42826 | E5: 2.9850746 | F5: 2020 | G5: =AVERAGEIFS($E:$E,$B:$B,'Q2_YoY Trend'!F5) -> 6.3156967
A6: Rural+Urban | B6: 2017 | C6: 131.4 | D6: 42856 | E6: 2.1772939 | F6: 2022 | G6: =AVERAGEIFS($E:$E,$B:$B,'Q2_YoY Trend'!F6) -> 6.624065
A7: Rural+Urban | B7: 2017 | C7: 132 | D7: 42887 | E7: 1.4604151 | F7: 2023 | G7: =AVERAGEIFS($E:$E,$B:$B,'Q2_YoY Trend'!F7) -> 5.5756722
A8: Rural+Urban | B8: 2017 | C8: 134.2 | D8: 42917 | E8: 2.3646072
A9: Rural+Urban | B9: 2017 | C9: 135.4 | D9: 42948 | E9: 3.279939
A10: Rural+Urban | B10: 2017 | C10: 135.2 | D10: 42979 | E10: 3.2849503
A11: Rural+Urban | B11: 2017 | C11: 136.1 | D11: 43009 | E11: 3.5768645
A12: Rural+Urban | B12: 2017 | C12: 137.6 | D12: 43040 | E12: 4.8780488
A13: Rural+Urban | B13: 2017 | C13: 137.2 | D13: 43070 | E13: 5.2147239
A14: Rural+Urban | B14: 2018 | C14: 136.9 | D14: 43101 | E14: 5.0652341
A15: Rural+Urban | B15: 2018 | C15: 136.4 | D15: 43132 | E15: 4.4410413
A16: Rural+Urban | B16: 2018 | C16: 136.5 | D16: 43160 | E16: 4.2780749
A17: Rural+Urban | B17: 2018 | C17: 137.1 | D17: 43191 | E17: 4.576659
A18: Rural+Urban | B18: 2018 | C18: 137.8 | D18: 43221 | E18: 4.870624
A19: Rural+Urban | B19: 2018 | C19: 138.5 | D19: 43252 | E19: 4.9242424
A20: Rural+Urban | B20: 2018 | C20: 139.8 | D20: 43282 | E20: 4.1728763 | I20: Food, Fuel,and transport pressure were key Drivers
A21: Rural+Urban | B21: 2018 | C21: 140.4 | D21: 43313 | E21: 3.6927622
A22: Rural+Urban | B22: 2018 | C22: 140.2 | D22: 43344 | E22: 3.6982249
A23: Rural+Urban | B23: 2018 | C23: 140.8 | D23: 43374 | E23: 3.4533431
A24: Rural+Urban | B24: 2018 | C24: 140.8 | D24: 43405 | E24: 2.3255814
A25: Rural+Urban | B25: 2018 | C25: 140.1 | D25: 43435 | E25: 2.1137026
A26: Rural+Urban | B26: 2019 | C26: 139.6 | D26: 43466 | E26: 1.9722425
A27: Rural+Urban | B27: 2019 | C27: 139.9 | D27: 43497 | E27: 2.5659824
A28: Rural+Urban | B28: 2019 | C28: 140.4 | D28: 43525 | E28: 2.8571429
A29: Rural+Urban | B29: 2019 | C29: 142 | D29: 43586 | E29: 3.5740336
A30: Rural+Urban | B30: 2019 | C30: 142.9 | D30: 43617 | E30: 3.701016
A31: Rural+Urban | B31: 2019 | C31: 144.2 | D31: 43647 | E31: 4.1155235
A32: Rural+Urban | B32: 2019 | C32: 145 | D32: 43678 | E32: 3.7195994
... A77: Rural+Urban | B77: 2023 | C77: 179.1 | D77: 45047 | E77: 4.3098427

Sheet  Q3_Food_Analysis
A1: Sector | B1: Year | C1: Month | D1: Cereals and products | E1: Meat and fish | F1: Egg | G1: Milk and products | H1: Oils and fats | I1: Fruits | J1: Vegetables | K1: Pulses and products | L1: Sugar and Confectionery | M1: Spices | N1: Non-alcoholic beverages | O1: Prepared meals, snacks, sweets etc. | P1: Food and beverages | Q1: Pan, tobacco and intoxicants | R1: Clothing | S1: Footwear | T1: Clothing and footwear | U1: Housing | V1: Fuel and light | W1: Household goods and services | X1: Health | Y1: Transport and communication | Z1: Recreation and amusement | AA1: Education | AB1: Personal care and effects | AC1: Miscellaneous | AD1: General index | AE1: Date | AF1: Food_Index | AG1: Food MoM%
A2: Rural+Urban | B2: 2022 | C2: June | D2: 155 | E2: 219.4 | F2: 170.8 | G2: 165.8 | H2: 200.9 | I2: 169.7 | J2: 182.3 | K2: 164.3 | L2: 119.9 | M2: 187.1 | N2: 167.9 | O2: 183.9 | P2: 174.9 | Q2: 194.3 | R2: 177.1 | S2: 169.9 | T2: 176 | U2: 166.8 | V2: 176 | W2: 166.4 | X2: 175.4 | Y2: 161.1 | Z2: 165.8 | AA2: 169 | AB2: 169.4 | AC2: 167.5 | AD2: 172.6 | AE2: 44713 | AF2: =AVERAGE(D2:O2) -> 173.91667
A3: Rural+Urban | B3: 2022 | C3: July | D3: 156.5 | E3: 213 | F3: 175.2 | G3: 166.6 | H3: 195.8 | I3: 174.2 | J3: 182.1 | K3: 164.3 | L3: 120 | M3: 190 | N3: 168.4 | O3: 185.2 | P3: 175 | Q3: 194.6 | R3: 178.3 | S3: 171.3 | T3: 177.3 | U3: 167.8 | V3: 179.6 | W3: 167.4 | X3: 176.1 | Y3: 161.6 | Z3: 166.3 | AA3: 171.4 | AB3: 169.7 | AC3: 168.4 | AD3: 173.4 | AE3: 44743 | AF3: =AVERAGE(D3:O3) -> 174.275 | AG3: =((AF3-AF2)/AF2)*100 -> 0.20603737
A4: Rural+Urban | B4: 2022 | C4: August | D4: 160.3 | E4: 206.5 | F4: 169.2 | G4: 168.1 | H4: 192.4 | I4: 172.9 | J4: 186.7 | K4: 167.2 | L4: 120.9 | M4: 193.6 | N4: 168.8 | O4: 186.3 | P4: 176.3 | Q4: 195 | R4: 179.5 | S4: 172.7 | T4: 178.5 | U4: 169 | V4: 178.8 | W4: 168.5 | X4: 176.8 | Y4: 161.9 | Z4: 166.9 | AA4: 172.3 | AB4: 171.2 | AC4: 169.1 | AD4: 174.3 | AE4: 44774 | AF4: =AVERAGE(D4:O4) -> 174.40833 | AG4: =((AF4-AF3)/AF3)*100 -> 0.076507436
A5: Rural+Urban | B5: 2022 | C5: September | D5: 163.5 | E5: 209.2 | F5: 169.7 | G5: 169.7 | H5: 188.7 | I5: 165.7 | J5: 191.8 | K5: 169.1 | L5: 121.6 | M5: 197.3 | N5: 169.4 | O5: 187.4 | P5: 177.8 | Q5: 195.9 | R5: 180.9 | S5: 174.3 | T5: 179.9 | U5: 169.5 | V5: 179.5 | W5: 169.5 | X5: 177.8 | Y5: 162.3 | Z5: 167.6 | AA5: 173.1 | AB5: 170.9 | AC5: 169.7 | AD5: 175.3 | AE5: 44805 | AF5: =AVERAGE(D5:O5) -> 175.25833 | AG5: =((AF5-AF4)/AF4)*100 -> 0.48736203
A6: Rural+Urban | B6: 2022 | C6: October | D6: 165.2 | E6: 210.9 | F6: 170.9 | G6: 170.9 | H6: 186.5 | I6: 163.8 | J6: 199.7 | K6: 169.8 | L6: 121.9 | M6: 199.9 | N6: 169.9 | O6: 188.3 | P6: 179.6 | Q6: 196.3 | R6: 181.9 | S6: 175.3 | T6: 181 | U6: 171.2 | V6: 180.5 | W6: 170.4 | X6: 178.7 | Y6: 162.9 | Z6: 168.2 | AA6: 173.4 | AB6: 172.1 | AC6: 170.5 | AD6: 176.7 | AE6: 44835 | AF6: =AVERAGE(D6:O6) -> 176.475 | AG6: =((AF6-AF5)/AF5)*100 -> 0.6942133
A7: Rural+Urban | B7: 2022 | C7: November | D7: 167.4 | E7: 209.4 | F7: 181.4 | G7: 172.3 | H7: 188.9 | I7: 160.7 | J7: 183.1 | K7: 170.5 | L7: 122.1 | M7: 202.8 | N7: 170.4 | O7: 189.5 | P7: 178.3 | Q7: 196.9 | R7: 183.1 | S7: 176.2 | T7: 182.1 | U7: 171.8 | V7: 181.3 | W7: 171.4 | X7: 179.8 | Y7: 163 | Z7: 168.5 | AA7: 173.7 | AB7: 173.6 | AC7: 171.1 | AD7: 176.5 | AE7: 44866 | AF7: =AVERAGE(D7:O7) -> 176.54167 | AG7: =((AF7-AF6)/AF6)*100 -> 0.037776833
A8: Rural+Urban | B8: 2022 | C8: December | D8: 169.2 | E8: 209 | F8: 190.2 | G8: 173.6 | H8: 188.5 | I8: 158 | J8: 159.9 | K8: 170.8 | L8: 121.8 | M8: 205.2 | N8: 171 | O8: 190.3 | P8: 175.9 | Q8: 197.3 | R8: 184 | S8: 177 | T8: 183 | U8: 170.7 | V8: 182 | W8: 172.1 | X8: 181.1 | Y8: 163.4 | Z8: 168.9 | AA8: 174.1 | AB8: 175.8 | AC8: 172 | AD8: 175.7 | AE8: 44896 | AF8: =AVERAGE(D8:O8) -> 175.625 | AG8: =((AF8-AF7)/AF7)*100 -> -0.51923531
A9: Rural+Urban | B9: 2023 | C9: January | D9: 173.8 | E9: 210.7 | F9: 194.5 | G9: 174.6 | H9: 187.2 | I9: 158.3 | J9: 153.9 | K9: 170.9 | L9: 121.1 | M9: 208.4 | N9: 171.4 | O9: 191.2 | P9: 176.7 | Q9: 198.2 | R9: 184.9 | S9: 177.6 | T9: 183.8 | U9: 172.1 | V9: 182 | W9: 172.9 | X9: 182.3 | Y9: 163.6 | Z9: 169.5 | AA9: 174.3 | AB9: 178.6 | AC9: 172.8 | AD9: 176.5 | AE9: 44927 | AF9: =AVERAGE(D9:O9) -> 176.33333 | AG9: =((AF9-AF8)/AF8)*100 -> 0.40332147
